<?xml version="1.0" ?>
<robot name="ackerman_plus">
  <!-- LINK BASE -->
  <link name="base_link">
    <visual>
      <origin rpy="0.0 0.0 0.0" xyz="0.0 0.0 0.15"/>
      <geometry>
        <box size="0.5 0.25 0.07"/>
      </geometry>
      <material name="Blue">
        <color rgba="0.0 0.0 1.0 1.0"/>
      </material>
    </visual>
    <collision>
      <origin rpy="0.0 0.0 0.0" xyz="0.0 0.0 0.15"/>
      <geometry>
        <box size="0.5 0.25 0.07"/>
      </geometry>
    </collision>
    <inertial>
      <origin rpy="1.5707963267948966 0 1.5707963267948966" xyz="0 0 0"/>
      <mass value="1500"/>
      <inertia ixx="31.8625" ixy="0.0" ixz="0.0" iyy="39.0625" iyz="0.0" izz="8.425"/>
    </inertial>
  </link>
  <!-- LINK SISTEMA GIRO RUEDA DERECHA -->
  <link name="right_wheel_turn">
    <visual>
      <origin rpy="0.0 0.0 0.0" xyz="0.0 0.0 0.0"/>
      <geometry>
        <cylinder length="0.025" radius="0.05"/>
      </geometry>
      <material name="Green">
        <color rgba="0.0 1.0 0.0 1.0"/>
      </material>
    </visual>
    <collision>
      <origin rpy="0.0 0.0 0.0" xyz="0.0 0.0 0.0"/>
      <geometry>
        <cylinder length="0.025" radius="0.05"/>
      </geometry>
    </collision>
    <inertial>
      <origin rpy="1.5707963267948966 0 0" xyz="0 0 0"/>
      <mass value="1"/>
      <inertia ixx="0.0006770833333333335" ixy="0" ixz="0" iyy="0.0006770833333333335" iyz="0" izz="0.0012500000000000002"/>
    </inertial>
  </link>
  <!-- LINK SISTEMA GIRO RUEDA IZQUIERDA -->
  <link name="left_wheel_turn">
    <visual>
      <origin rpy="0.0 0.0 0.0" xyz="0.0 0.0 0.0"/>
      <geometry>
        <cylinder length="0.025" radius="0.05"/>
      </geometry>
      <material name="Green">
        <color rgba="0.0 1.0 0.0 1.0"/>
      </material>
    </visual>
    <collision>
      <origin rpy="0.0 0.0 0.0" xyz="0.0 0.0 0.0"/>
      <geometry>
        <cylinder length="0.025" radius="0.05"/>
      </geometry>
    </collision>
    <inertial>
      <origin rpy="1.5707963267948966 0 0" xyz="0 0 0"/>
      <mass value="1"/>
      <inertia ixx="0.0006770833333333335" ixy="0" ixz="0" iyy="0.0006770833333333335" iyz="0" izz="0.0012500000000000002"/>
    </inertial>
  </link>
  <!-- LINK VOLANTE-->
  <link name="steering_wheel">
    <visual>
      <origin rpy="0.0 0.0 0.0" xyz="0.0 0.0 0.0"/>
      <geometry>
        <cylinder length="0.025" radius="0.05"/>
      </geometry>
      <material name="Green">
        <color rgba="0.0 1.0 0.0 1.0"/>
      </material>
    </visual>
    <collision>
      <origin rpy="0.0 0.0 0.0" xyz="0.0 0.0 0.0"/>
      <geometry>
        <cylinder length="0.025" radius="0.05"/>
      </geometry>
    </collision>
    <inertial>
      <origin rpy="1.5707963267948966 0 0" xyz="0 0 0"/>
      <mass value="1"/>
      <inertia ixx="0.0006770833333333335" ixy="0" ixz="0" iyy="0.0006770833333333335" iyz="0" izz="0.0012500000000000002"/>
    </inertial>
  </link>
  <!-- LINK RUEDA TRASERA IZQUIERDA -->
  <link name="left_wheel_rear">
    <visual>
      <origin rpy="1.57 0.0 0.0" xyz="0.0 0.0 0.0"/>
      <geometry>
        <cylinder length="0.05" radius="0.1"/>
      </geometry>
      <material name="Black">
        <color rgba="0.0 0.0 0.0 1.0"/>
      </material>
    </visual>
    <collision>
      <origin rpy="1.57 0.0 0.0" xyz="0.0 0.0 0.0"/>
      <geometry>
        <sphere radius="0.1"/>
      </geometry>
    </collision>
    <inertial>
      <origin rpy="1.5707963267948966 0 0" xyz="0 0 0"/>
      <mass value="11"/>
      <inertia ixx="0.02979166666666667" ixy="0" ixz="0" iyy="0.02979166666666667" iyz="0" izz="0.05500000000000001"/>
    </inertial>
  </link>
  <!-- LINK RUEDA TRASERA DERECHA -->
  <link name="right_wheel_rear">
    <visual>
      <origin rpy="1.57 0.0 0.0" xyz="0.0 0.0 0.0"/>
      <geometry>
        <cylinder length="0.05" radius="0.1"/>
      </geometry>
      <material name="Black">
        <color rgba="0.0 0.0 0.0 1.0"/>
      </material>
    </visual>
    <collision>
      <origin rpy="1.57 0.0 0.0" xyz="0.0 0.0 0.0"/>
      <geometry>
        <sphere radius="0.1"/>
      </geometry>
    </collision>
    <inertial>
      <origin rpy="1.5707963267948966 0 0" xyz="0 0 0"/>
      <mass value="11"/>
      <inertia ixx="0.02979166666666667" ixy="0" ixz="0" iyy="0.02979166666666667" iyz="0" izz="0.05500000000000001"/>
    </inertial>
  </link>
  <!-- LINK RUEDA FRONTAL IZQUIERDA -->
  <link name="left_wheel_front">
    <visual>
      <origin rpy="1.57 0.0 0.0" xyz="0.0 0.0 0.0"/>
      <geometry>
        <cylinder length="0.05" radius="0.1"/>
      </geometry>
      <material name="Black">
        <color rgba="0.0 0.0 0.0 1.0"/>
      </material>
    </visual>
    <collision>
      <origin rpy="1.57 0.0 0.0" xyz="0.0 0.0 0.0"/>
      <geometry>
        <sphere radius="0.1"/>
      </geometry>
    </collision>
    <inertial>
      <origin rpy="1.5707963267948966 0 0" xyz="0 0 0"/>
      <mass value="11"/>
      <inertia ixx="0.02979166666666667" ixy="0" ixz="0" iyy="0.02979166666666667" iyz="0" izz="0.05500000000000001"/>
    </inertial>
  </link>
  <!-- LINK RUEDA FRONTAL DERECHA -->
  <link name="right_wheel_front">
    <visual>
      <origin rpy="1.57 0.0 0.0" xyz="0.0 0.0 0.0"/>
      <geometry>
        <cylinder length="0.05" radius="0.1"/>
      </geometry>
      <material name="Black">
        <color rgba="0.0 0.0 0.0 1.0"/>
      </material>
    </visual>
    <collision>
      <origin rpy="1.57 0.0 0.0" xyz="0.0 0.0 0.0"/>
      <geometry>
        <sphere radius="0.1"/>
      </geometry>
    </collision>
    <inertial>
      <origin rpy="1.5707963267948966 0 0" xyz="0 0 0"/>
      <mass value="11"/>
      <inertia ixx="0.02979166666666667" ixy="0" ixz="0" iyy="0.02979166666666667" iyz="0" izz="0.05500000000000001"/>
    </inertial>
  </link>
  <!-- JOINTS -->
  <!--Enlace entre sistema de giro con rueda derecha superior-->
  <joint name="front_right_steer_joint" type="revolute">
    <origin rpy="0 0.0 0.0" xyz="0.2 -0.15 0.21250000000000002"/>
    <parent link="base_link"/>
    <child link="right_wheel_turn"/>
    <axis xyz="0.0 0.0 1.0"/>
    <limit effort="100" lower="-0.6458" upper="0.6458" velocity="0.5"/>
  </joint>
  <!--Enlace entre sistema de giro con rueda izquierda superior-->
  <joint name="front_left_steer_joint" type="revolute">
    <origin rpy="0 0.0 0.0" xyz="0.2 0.15 0.21250000000000002"/>
    <parent link="base_link"/>
    <child link="left_wheel_turn"/>
    <axis xyz="0.0 0.0 1.0"/>
    <limit effort="100" lower="-0.6458" upper="0.6458" velocity="0.5"/>
  </joint>
  <!--Enlace para el volante de dirección-->
  <joint name="steering_joint" type="continuous">
    <origin rpy="0.0 0.0 0.0" xyz="0.2 0.0 0.21250000000000002"/>
    <parent link="base_link"/>
    <child link="steering_wheel"/>
    <axis xyz="0 0 1"/>
  </joint>
  <!--Enlace entre rueda izquierda frontal y sistema de giro-->
  <joint name="front_right_wheel_joint" type="continuous">
    <parent link="right_wheel_turn"/>
    <child link="right_wheel_front"/>
    <origin rpy="0 0.0 0.0" xyz="0.0 0.0 -0.1125"/>
    <axis xyz="0.0 1 0.0"/>
  </joint>
  <!--Enlace entre rueda derecha frontal y sistema de giro-->
  <joint name="front_left_wheel_joint" type="continuous">
    <parent link="left_wheel_turn"/>
    <child link="left_wheel_front"/>
    <origin rpy="0 0.0 0.0" xyz="0.0 0.0 -0.1125"/>
    <axis xyz="0.0 1 0.0"/>
  </joint>
  <!--Enlace entre rueda izquierda inferior y base-->
  <joint name="rear_left_wheel_joint" type="continuous">
    <parent link="base_link"/>
    <child link="left_wheel_rear"/>
    <origin rpy="0 0.0 0.0" xyz="-0.2 0.15 0.1"/>
    <axis xyz="0.0 1.0 0.0"/>
  </joint>
  <!--Enlace entre rueda izquierda inferior y base-->
  <joint name="rear_right_wheel_joint" type="continuous">
    <parent link="base_link"/>
    <child link="right_wheel_rear"/>
    <origin rpy="0 0.0 0.0" xyz="-0.2 -0.15 0.1"/>
    <axis xyz="0.0 1.0 0.0"/>
  </joint>
</robot>
